Erro: Details: Traceback (most recent call last): File "/mnt/c/Users/josep/Documents/DocumentsWSL/1-PROJECTS/sanctum-cognitionis/app.py", line 211, in chat_messages new_chat_message = chat_history.send_ai_message( File "/mnt/c/Users/josep/Documents/DocumentsWSL/1-PROJECTS/sanctum-cognitionis/praesentatio_cognitionis/chat_history.py", line 50, in send_ai_message ai_response_stream = self.llm_model.send_stream_chat_message( File "/mnt/c/Users/josep/Documents/DocumentsWSL/1-PROJECTS/sanctum-cognitionis/servitium_cognitionis/llms/gemini/dev_models.py", line 61, in send_stream_chat_message ai_response_stream = self._model_chats[session_id].send_message(messages, stream=True) File "/home/joe/anaconda3/envs/sanctum-cognitionis/lib/python3.10/site-packages/google/generativeai/generative_models.py", line 474, in send_message response = self.model.generate_content( File "/home/joe/anaconda3/envs/sanctum-cognitionis/lib/python3.10/site-packages/google/generativeai/generative_models.py", line 260, in generate_content return generation_types.GenerateContentResponse.from_iterator(iterator) File "/home/joe/anaconda3/envs/sanctum-cognitionis/lib/python3.10/site-packages/google/generativeai/types/generation_types.py", line 451, in from_iterator response = next(iterator) File "/home/joe/anaconda3/envs/sanctum-cognitionis/lib/python3.10/site-packages/google/api_core/grpc_helpers.py", line 116, in next return next(self._wrapped) File "/home/joe/anaconda3/envs/sanctum-cognitionis/lib/python3.10/site-packages/grpc/_channel.py", line 543, in next return self._next() File "/home/joe/anaconda3/envs/sanctum-cognitionis/lib/python3.10/site-packages/grpc/_channel.py", line 950, in _next raise StopIteration() StopIteration
